Я пытался пометить функцию merge_and_write через декоратор @pytest.fixture(autouse=True), но у меня тест вываливался всегда с ошибкой.
Не знаю, насколько точно я сделал правильно задание, но для test1 я использовал декоратор @pytest.mark.parametrize и прокинул данные в функции.
Если ввести команду "pytest test.py" в терминале, то выведется информация о запущенном тесте.
В конечном итоге, у нас функции отрабатывают по 2 раза, где видно, что у нас тест прошёл 2 раза и не прошёл 2 раза.
